Workbook

Sheet BUGET_PNRR_20251006
A1: ID_FIN_BUGETE | B1: COMP | C1: MAS | D1: SUB_MAS | E1: COORDONATOR | F1: FINANTARE | G1: MASURA_TITLU | H1: ALOCARE_FINANCIARA
A2: 2 | B2: C1 | C2: I1 | E2: MMAP | F2: loan | G2: I1. Extinderea sistemelor de apă și canalizare în aglomerări mai mari de 2000 de locuitori echivalenți | H2: 244838539
A3: 3 | B3: C1 | C3: I2 | E3: MMAP | F3: loan | G3: I2. Colectarea apelor uzate în aglomerări mai mici de 2.000 de locuitori echivalenți, care împiedică atingerea unei stări bune a corpurilor de apă și/sau afectează arii naturale protejate | H3: 57974587
A4: 5 | B4: C1 | C4: I4 | E4: MMAP | F4: loan | G4: I4. Adaptarea la schimbările climatice prin automatizarea și digitalizarea echipamentelor de evacuare și stocare a apei la acumulări existente pentru asigurarea debitului ecologic și creșterea siguranței alimentării cu apă a populației și reducerea riscului la inundații. | H4: 33003856
A5: 7 | B5: C1 | C5: I5 | E5: MMAP | F5: loan | G5: I5. Dotarea adecvată a administrațiilor bazinale pentru monitorizarea infrastructurii, prevenirea și gestionarea situațiilor de urgență | H5: 35000000
A6: 8 | B6: C1 | C6: I6 | E6: MMAP | F6: grant | G6: I6. Realizarea cadastrului apelor | H6: 30000000
A7: 11 | B7: C2 | C7: I1 | E7: MMAP | F7: grant | G7: I1. Campania națională de împădurire și reîmpădurire, inclusiv păduri urbane | H7: 307547498
A8: 12 | B8: C2 | C8: I2 | E8: MMAP | F8: grant | G8: I2. Dezvoltarea de capacități moderne de producere a materialului forestier de reproducere | H8: 50000000
A9: 13 | B9: C2 | C9: I3 | E9: MMAP | F9: grant | G9: I3. Actualizarea planurilor de management aprobate și identificarea zonelor potențiale de protecție strictă în habitate naturale terestre și marine în vederea punerii în aplicare a Strategiei UE privind biodiversitatea pentru 2030 | H9: 5000000
A10: 16 | B10: C2 | C10: I4 | E10: MMAP | F10: grant | G10: I4. Investiții integrate de reconstrucție ecologică a habitatelor și conservarea speciilor aferente pajiștilor, zonelor acvatice și dependente de apă | H10: 10001000
A11: 20 | B11: C2 | C11: I5 | E11: MMAP | F11: grant | G11: I5. Sisteme integrate de reducere a riscurilor generate de viituri torențiale în bazinete forestiere expuse unor astfel de fenomene | H11: 22000000
A12: 21 | B12: C3 | C12: I1 | D12: 1 | E12: MMAP | F12: grant | G12: I1. Dezvoltarea, modernizarea și completarea sistemelor de management integrat al deșeurilor municipale la nivel de județ sau la nivel de orașe/comune | H12: 240106200
A13: 149 | B13: C3 | C13: I1 | D13: 2 | E13: MMAP | F13: loan | G13: I1. Dezvoltarea, modernizarea și completarea sistemelor de management integrat al deșeurilor municipale la nivel de județ sau la nivel de orașe/comune | H13: 165643845
A14: 25 | B14: C3 | C14: I2 | E14: MMAP | F14: loan | G14: I2. Dezvoltarea infrastructurii pentru managementul gunoiului de grajd și al altor deșeuri agricole compostabile | H14: 50196850
A15: 26 | B15: C3 | C15: I3 | E15: MMAP | F15: grant | G15: I3. Dezvoltarea capacităților instituționale de monitorizare publică și control pentru gestionarea deșeurilor și prevenirea poluării | H15: 13000000
A16: 29 | B16: C4 | C16: I1 | E16: MTI | F16: loan | G16: I1. Modernizarea și reînnoirea infrastructurii feroviare | H16: 1874376400
A17: 30 | B17: C4 | C17: I2 | E17: MTI | F17: loan | G17: I2. Material rulant feroviar | H17: 280829800
A18: 32 | B18: C4 | C18: I3 | D18: 1 | E18: MTI | F18: loan | G18: I3. Dezvoltarea infrastructurii rutiere durabile aferente rețelei TEN-T, taxarea drumurilor, managementul traficului și siguranța rutieră | H18: 1098821134
A19: 174 | B19: C4 | C19: I3 | D19: 2 | E19: MTI | F19: grant | G19: I3. Dezvoltarea infrastructurii rutiere durabile aferente rețelei TEN-T, taxarea drumurilor, managementul traficului și siguranța rutieră - 5 loturi A7 si Infrastructura aferentă operaționalizării sistemelor de trafic inteligent – centru de management al traficului, sisteme de informare a utilizatorilor, interoperabilitatea sistemelor de transport | H19: 2169200266
A20: 175 | B20: C5 | C20: I1 | D20: 1 | E20: MDLPA | F20: grant | G20: I1. Instituirea unui fond pentru Valul Renovării care să finanțeze lucrări de îmbunătățire a eficienței energetice a fondului construit | H20: 1390241851
A21: 35 | B21: C5 | C21: I1 | D21: 2 | E21: MDLPA | F21: loan | G21: I1. Instituirea unui fond pentru Valul Renovării care să finanțeze lucrări de îmbunătățire a eficienței energetice a fondului construit | H21: 523160864
A22: 36 | B22: C5 | C22: I2 | E22: MDLPA | F22: loan | G22: I2. Implementarea Registrului național al clădirilor | H22: 5000000
A23: 38 | B23: C5 | C23: I4 | E23: MC | F23: loan | G23: I4. Economie circulară și creșterea eficienței energetice a clădirilor istorice | H23: 14850000
A24: 41 | B24: C6 | C24: I2 | E24: MENERGIEI | F24: loan | G24: I2. Capacitățile de producție a hidrogenului verde care să fie utilizat pentru stocarea energiei electrice și/sau pentru decarbonizarea industriei | H24: 86500000
A25: 42 | B25: C6 | C25: I3 | E25: MENERGIEI | F25: loan | G25: I3. Dezvoltarea unei producții combinate de energie termică și energie electrică (CHP) pe gaz flexibile și de înaltă eficiență în sectorul încălzirii centralizate, în vederea atingerii unei decarbonizări adânci | H25: 86377743
A26: 43 | B26: C6 | C26: I4 | D26: 2 | E26: MENERGIEI | F26: loan | G26: I4. Lanț industrial de producție și/sau asamblare și/sau reciclare a bateriilor, a celulelor și panourilor fotovoltaice (inclusiv echipamente auxiliare) și noi capacități de stocare a energiei electrice | H26: 50000000
A27: 176 | B27: C6 | C27: I4 | D27: 3 | E27: MENERGIEI | F27: grant | G27: I4. Lanț industrial de producție și/sau asamblare și/sau reciclare a bateriilor, a celulelor și panourilor fotovoltaice (inclusiv echipamente auxiliare) și noi capacități de stocare a energiei electrice | H27: 80000000
A28: 44 | B28: C6 | C28: I5 | E28: MENERGIEI | F28: grant | G28: I5. Asigurarea eficienței energetice în sectorul industrial | H28: 64000000
A29: 46 | B29: C7 | C29: I1 | E29: MEDAT | F29: grant | G29: I1. Implementarea infrastructurii de cloud guvernamental | H29: 374728570
A30: 47 | B30: C7 | C30: I2 | E30: MEDAT | F30: grant | G30: I2. Dezvoltarea cloudului și migrarea în cloud. | H30: 187050420
A31: 48 | B31: C7 | C31: I3 | D31: 1 | E31: MS | F31: grant | G31: I3. Realizarea sistemului de eHealth și telemedicină - I3.1 Redimensionare, standardizare și optimizare a Platformei informatice din asigurările de sănătate (PIAS) | H31: 100000000
A32: 177 | B32: C7 | C32: I3 | D32: 2 | E32: MS | F32: grant | G32: I3. Realizarea sistemului de eHealth și telemedicină - I3.2. Digitalizarea instituțiilor cu atribuții în domeniul sanitar aflate în subordinea MS | H32: 100000000
A33: 178 | B33: C7 | C33: I3 | D33: 3 | E33: MS | F33: grant | G33: I3. Realizarea sistemului de eHealth și telemedicină - I3.3 Digitalizarea a 200 de unități sanitare publice | H33: 100000000
A34: 49 | B34: C7 | C34: I4 | E34: MJ | F34: grant | G34: I4. Digitalizarea sistemului judiciar | H34: 242310000
A35: 50 | B35: C7 | C35: I5 | E35: MMAP | F35: grant | G35: I5. Digitalizare în domeniul mediului | H35: 47951280
A36: 51 | B36: C7 | C36: I6 | E36: MMFTSS | F36: grant | G36: I6. Digitalizarea în domeniul muncii și protecției sociale | H36: 85000000
A37: 52 | B37: C7 | C37: I7 | E37: ANAP | F37: grant | G37: I7. Implementarea formularelor electronice eForms în domeniul achizițiilor publice | H37: 851600
A38: 53 | B38: C7 | C38: I8 | E38: MAI | F38: grant | G38: I8. Cartea de identitate electronică și semnătura digitală | H38: 129000000
A39: 54 | B39: C7 | C39: I9 | E39: MIPE | F39: grant | G39: I9. Digitalizarea sectorului organizațiilor neguvernamentale | H39: 12000000
A40: 55 | B40: C7 | C40: I10 | E40: ANFP | F40: grant | G40: I10. Transformarea digitală în managementul funcției publice | H40: 10000000
...

Sheet StatusPNRR
A1: Componenta | B1: Măsura | C1: Coordonator | D1: Finanțare | E1: Titlul măsurii | F1: Alocare Finaciară (euro Exclusiv Tva) | G1: Contractare (lei Exclusiv Tva) | H1: Executat (lei) | I1: Executat (euro) | J1: Executat (%)
A2: C1 | B2: I1 | C2: MMAP | D2: loan | E2: I1. Extinderea sistemelor de apă și canalizare în aglomerări mai mari de 2000 de locuitori echivalenți | F2: 244838539 | G2: 2146697258 | H2: 250458914 | I2: 50017454 | J2: 0.204
A3: C1 | B3: I2 | C3: MMAP | D3: loan | E3: I2. Colectarea apelor uzate în aglomerări mai mici de 2.000 de locuitori echivalenți, care împiedică atingerea unei stări bune a corpurilor de apă și/sau afectează arii naturale protejate | F3: 57974587 | G3: 511355717 | H3: 125462024 | I3: 25049710 | J3: 0.432
A4: C1 | B4: I4 | C4: MMAP | D4: loan | E4: I4. Adaptarea la schimbările climatice prin automatizarea și digitalizarea echipamentelor de evacuare și stocare a apei la acumulări existente pentru asigurarea debitului ecologic și creșterea siguranței alimentării cu apă a populației și reducerea riscului la inundații. | F4: 33003856 | G4: 1610434017 | H4: 5934536 | I4: 1185419 | J4: 0.036
A5: C1 | B5: I5 | C5: MMAP | D5: loan | E5: I5. Dotarea adecvată a administrațiilor bazinale pentru monitorizarea infrastructurii, prevenirea și gestionarea situațiilor de urgență | F5: 35000000 | G5: 174300000 | H5: 62421654 | I5: 12484331 | J5: 0.357
A6: C1 | B6: I6 | C6: MMAP | D6: grant | E6: I6. Realizarea cadastrului apelor | F6: 30000000 | G6: 149400000 | H6: 2500000 | I6: 499002 | J6: 0.017
A7: C1 | B7: R2 | C7: MMAP | D7: loan | E7: R2. Reconfigurarea actualului mecanism economic al ANAR în vederea asigurării modernizării și întreținerii sistemului național de gospodărire a apelor, precum și a implementării corespunzătoare a Directivei-cadru privind apa și a Directivei privind inundațiile | F7: 2500000 | G7: 12450000 | H7: 12395484 | I7: 2478414 | J7: 0.991
A8: C2 | B8: I1 | C8: MMAP | D8: grant | E8: I1. Campania națională de împădurire și reîmpădurire, inclusiv păduri urbane | F8: 307547498 | G8: 1162474234 | H8: 365879763 | I8: 73088923 | J8: 0.238
A9: C2 | B9: I2 | C9: MMAP | D9: grant | E9: I2. Dezvoltarea de capacități moderne de producere a materialului forestier de reproducere | F9: 50000000 | G9: 177044699 | H9: 88237976 | I9: 17622067 | J9: 0.352
A10: C2 | B10: I3 | C10: MMAP | D10: grant | E10: I3. Actualizarea planurilor de management aprobate și identificarea zonelor potențiale de protecție strictă în habitate naturale terestre și marine în vederea punerii în aplicare a Strategiei UE privind biodiversitatea pentru 2030 | F10: 5000000 | G10: 0 | H10: 0 | I10: 0 | J10: 0
A11: C2 | B11: I4 | C11: MMAP | D11: grant | E11: I4. Investiții integrate de reconstrucție ecologică a habitatelor și conservarea speciilor aferente pajiștilor, zonelor acvatice și dependente de apă | F11: 10001000 | G11: 331051286 | H11: 0 | I11: 0 | J11: 0
A12: C2 | B12: I5 | C12: MMAP | D12: grant | E12: I5. Sisteme integrate de reducere a riscurilor generate de viituri torențiale în bazinete forestiere expuse unor astfel de fenomene | F12: 22000000 | G12: 109560000 | H12: 64129183 | I12: 12817720 | J12: 0.583
A13: C2 | B13: R1 | C13: MMAP | D13: grant | E13: R1. Reforma sistemului de management și a celui privind guvernanța în domeniul forestier prin dezvoltarea unei noi Strategii forestiere naționale și a legislației subsecvente | F13: 1000000 | G13: 5000000 | H13: 3307000 | I13: 661400 | J13: 0.661
... A147: C16 | B147: R2 | C147: MDLPA | D147: grant | E147: R2. Înființarea de ghișee unice pentru furnizarea către prosumatori de servicii de consiliere în domeniul energiei pentru renovările ce vizează eficiența energetică și producția de energie din surse regenerabile | F147: 431438 | G147: 0 | H147: 0 | I147: 0 | J147: 0
F148: =SUM(F2:F147) -> 21409459031
F149: =SUMIF(C2:C147,"MC",F2:F147) -> 33000000
F150: =SUMIF(A3:A148,"C11",F3:F148) -> 190616081

Sheet Dashboard
C1: Dashboard | D1: Status | E1: Diferente
A2: C1 | B2: Managementul apei | C2: 463.55 | D2: =SUMIF(BUGET_PNRR_20251006!B2:B147,A2,BUGET_PNRR_20251006!H2:H147)/1000000 -> 403.31698 | E2: =C2-D2 -> 60.233018
A3: C2 | B3: Păduri și protecția biodiversității | C3: 381.29 | D3: =SUMIF(BUGET_PNRR_20251006!B3:B148,A3,BUGET_PNRR_20251006!H3:H148)/1000000 -> 395.5485 | E3: =C3-D3 -> -14.258498
A4: C3 | B4: Managementul deșeurilor | C4: 428.76 | D4: =SUMIF(BUGET_PNRR_20251006!B4:B149,A4,BUGET_PNRR_20251006!H4:H149)/1000000 -> 468.94689 | E4: =C4-D4 -> -40.186895
A5: C4 | B5: Transport sustenabil | C5: 2682.24 | D5: =SUMIF(BUGET_PNRR_20251006!B5:B150,A5,BUGET_PNRR_20251006!H5:H150)/1000000 -> 5452.2276 | E5: =C5-D5 -> -2769.9876
A6: C5 | B6: Valul Renovării | C6: 3340.03 | D6: =SUMIF(BUGET_PNRR_20251006!B6:B151,A6,BUGET_PNRR_20251006!H6:H151)/1000000 -> 1933.4027 | E6: =C6-D6 -> 1406.6273
A7: C6 | B7: Energie | C7: 2102.41 | D7: =SUMIF(BUGET_PNRR_20251006!B7:B152,A7,BUGET_PNRR_20251006!H7:H152)/1000000 -> 367.87774 | E7: =C7-D7 -> 1734.5323
A8: C7 | B8: Transformare digitală | C8: 2069.3 | D8: =SUMIF(BUGET_PNRR_20251006!B8:B153,A8,BUGET_PNRR_20251006!H8:H153)/1000000 -> 1739.4393 | E8: =C8-D8 -> 329.86066
A9: C8 | B9: Reforma fiscală și reforma sistemului de pensii | C9: 949.92 | D9: =SUMIF(BUGET_PNRR_20251006!B9:B154,A9,BUGET_PNRR_20251006!H9:H154)/1000000 -> 556.93251 | E9: =C9-D9 -> 392.98748
A10: C9 | B10: Suport pentru sectorul privat, cercetare, dezvoltare și inovare | C10: 1467.98 | D10: =SUMIF(BUGET_PNRR_20251006!B10:B155,A10,BUGET_PNRR_20251006!H10:H155)/1000000 -> 2129.4272 | E10: =C10-D10 -> -661.44717
A11: C10 | B11: Fondul local | C11: 882.1 | D11: =SUMIF(BUGET_PNRR_20251006!B11:B156,A11,BUGET_PNRR_20251006!H11:H156)/1000000 -> 1649.5388 | E11: =C11-D11 -> -767.43879
A12: C11 | B12: Turism și cultură | C12: 2181.84 | D12: =SUMIF(BUGET_PNRR_20251006!B12:B157,A12,BUGET_PNRR_20251006!H12:H157)/1000000 -> 190.61608 | E12: =C12-D12 -> 1991.2239
A13: C12 | B13: Sănătate | C13: 785.32 | D13: =SUMIF(BUGET_PNRR_20251006!B13:B158,A13,BUGET_PNRR_20251006!H13:H158)/1000000 -> 1337.3166 | E13: =C13-D13 -> -551.99661
... A17: C16 | B17: REPowerEU | C17: 248.1 | D17: =SUMIF(BUGET_PNRR_20251006!B17:B162,A17,BUGET_PNRR_20251006!H17:H162)/1000000 -> 1746.2038 | E17: =C17-D17 -> -1498.1038
C18: =SUM(C2:C17) -> 21409.55 | D18: =SUM(D2:D17) -> 21409.459 | E18: =C18-D18 -> 0.090969
